Workbook

Sheet DCF Model
B2: Tata Consultancy Services — Discounted Cash Flow Model
B3: INR crore unless stated · Consolidated · Valuation date 31-Mar-2026 (FY26 end) · Cross-checked against the Python DCF
B5: Italic blue blocks explain each stage; the green Notes column (far right) gives a plain-language reason for every line. Discounting uses simple 1/(1+WACC)^t arithmetic.
B6: Colours: blue = number you enter · black = calculated · yellow = check or update before relying on it
B8: STAGE 1 — Assumptions (the numbers you enter) | K8: NOTES — plain-language reasons
B9: These are the numbers you type in; everything else in the model is calculated from them. WACC and the two growth rates have the biggest effect on the final value, so they sit at the top. Cash and debt are here too, but they don't affect the yearly cash flows — they're used only at the very end, to turn the value of the business into the value for shareholders. Yellow cells are the ones to double-check or update before you rely on the model.
B15: Tax Rate | D15: 0.24 | K15: TCS paid about 24% of its profit in tax in FY26. We use the after-tax amount because a company only keeps what's left after tax, and that is what investors can actually claim.
B16: Discount Rate (WACC) | D16: =D142 -> 0.12689574 | K16: The yearly return TCS's investors expect, and the rate used to bring future cash back to today's value. It isn't typed in — it is worked out in Stage 6 and copied here.
B17: Terminal Growth (g) | D17: 0.05 | K17: The rate at which we assume cash flows keep growing forever, after the 5-year forecast. It must be smaller than WACC, or the terminal-value formula gives a meaningless (negative or infinite) answer.
B18: Explicit Growth | D18: 0.06 | K18: How fast cash flows grow during the 5 forecast years. 6% is based on TCS's recent revenue and profit growth, not a guess.
B19: Exit EV/EBITDA (x) | D19: 12 | K19: Used only as a second opinion on the terminal value: what a buyer might pay, as a multiple of one year's EBITDA. TCS trades at about 12 times EBITDA today, so we use 12.
B20: Valuation date (FY-end) | D20: 46112 | K20: The date we value the company as of. Everything is discounted back to here; the five forecast years are the March year-ends after it.
B21: Current Price (INR) | D21: 2465 | K21: Today's market price — the only figure we take from the market rather than estimate. We judge our own estimate against it. It changes daily, so update it before sharing the model.
B22: Shares Outstanding (cr) | D22: 361.81 | K22: The number of TCS shares (about 361.8 crore). We divide total equity value by this to get the value of one share.
B23: Debt (INR cr) | D23: 11283 | K23: What TCS owes — for TCS this is only lease obligations, as it has almost no borrowing. We subtract it when going from business value to shareholder value.
B24: Cash & Investments (INR cr) | D24: 50020 | K24: Cash plus investments TCS holds. Shareholders own this on top of the business, so we add it back at the end. It must include investments, where TCS keeps a large amount.
B25: Capex (INR cr) | D25: 4146 | K25: Money TCS spends each year on equipment and offices. It is real cash leaving the company, so we subtract it when working out free cash flow.
B27: Quick checks (calculated automatically)
B28: Net Cash (Cash & Inv − Debt) | D28: =D24-D23 -> 38737 | K28: Cash and investments minus debt = ₹38,737 cr. This is added when moving from business value to shareholder value. (Python's ₹55,000 was too high — more than the cash the company actually holds.)
B29: Implied Market Cap (Price × Shares) | D29: =D21*D22 -> 891861.65 | K29: Share price times number of shares = what the market currently values all of TCS's shares at.
B30: Implied Current EV (MktCap − Net Cash) | D30: =D29-D28 -> 853124.65 | K30: Market cap minus net cash = what the market thinks TCS's core business is worth. We compare our own business-value estimate against this.
B33: STAGE 2 — Unlevered Free Cash Flow (the cash the business makes) | K33: NOTES — plain-language reasons
B34: This works out the cash the business actually generates each year, available to everyone who funds it (lenders and shareholders) — which is why it is called 'unlevered', meaning before the effect of borrowing. We start from EBIT (operating profit, before interest and tax), not net profit, because net profit is already after interest and we don't want financing mixed in yet. From EBIT we take off tax, add back depreciation (not a real cash outflow), take off money spent on assets, and take off the extra cash tied up as the business grows. FY26 is the latest actual year; FY27 to FY31 grow from it at the chosen rate.
B40: Line item (FY26A = starting point) | D40: FY26A | E40: FY27F | F40: FY28F | G40: FY29F | H40: FY30F | I40: FY31F
B41: EBIT | D41: 66838 | E41: =D41*(1+$D$18) -> 70848.28 | F41: =E41*(1+$D$18) -> 75099.177 | G41: =F41*(1+$D$18) -> 79605.127 | H41: =G41*(1+$D$18) -> 84381.435 | I41: =H41*(1+$D$18) -> 89444.321 | K41: Operating profit before interest and tax. We get it from EBITDA (72,398) minus depreciation (5,560) = 66,838. Note: Screener calls EBITDA 'Operating Profit', so if you forget to subtract depreciation you overstate profit.
B42: Less: Cash Taxes | D42: =D41*$D$15 -> 16041.12 | E42: =E41*$D$15 -> 17003.587 | F42: =F41*$D$15 -> 18023.802 | G42: =G41*$D$15 -> 19105.231 | H42: =H41*$D$15 -> 20251.544 | I42: =I41*$D$15 -> 21466.637 | K42: Tax charged on that operating profit. We apply tax to EBIT itself, not to after-interest profit, so the result stays before-financing. The tax saved by using debt is dealt with inside WACC instead, so it isn't counted twice.
B43: Plus: D&A | D43: 5560 | E43: =D43*(1+$D$18) -> 5893.6 | F43: =E43*(1+$D$18) -> 6247.216 | G43: =F43*(1+$D$18) -> 6622.049 | H43: =G43*(1+$D$18) -> 7019.3719 | I43: =H43*(1+$D$18) -> 7440.5342 | K43: Depreciation was subtracted to reach EBIT, but it is not money leaving the company — it just spreads past spending over time in the accounts. Since we only want real cash, we add it back.
B44: Less: Capex | D44: =$D$25 -> 4146 | E44: =D44*(1+$D$18) -> 4394.76 | F44: =E44*(1+$D$18) -> 4658.4456 | G44: =F44*(1+$D$18) -> 4937.9523 | H44: =G44*(1+$D$18) -> 5234.2295 | I44: =H44*(1+$D$18) -> 5548.2832 | K44: Cash spent on new assets this year. The accounts spread this cost over several years as depreciation, but the cash goes out now, so a cash model subtracts the whole amount here.
B45: Less: Changes in NWC | D45: 2210 | E45: =D45*(1+$D$18) -> 2342.6 | F45: =E45*(1+$D$18) -> 2483.156 | G45: =F45*(1+$D$18) -> 2632.1454 | H45: =G45*(1+$D$18) -> 2790.0741 | I45: =H45*(1+$D$18) -> 2957.4785 | K45: As the business grows it ties up cash in unpaid customer bills and stock before it comes back. Watch the sign: the cash-flow statement showed this as −2,210 (cash used). This row is 'Less' and gets subtracted, so we enter +2,210 to get the same effect.
B46: Unlevered FCF | D46: =D41-D42+D43-D44-D45 -> 50000.88 | E46: =E41-E42+E43-E44-E45 -> 53000.933 | F46: =F41-F42+F43-F44-F45 -> 56180.989 | G46: =G41-G42+G43-G44-G45 -> 59551.848 | H46: =H41-H42+H43-H44-H45 -> 63124.959 | I46: =I41-I42+I43-I44-I45 -> 66912.457 | K46: What's left is the cash the whole business makes in a year, free for all investors. FY26 comes to 50,001 — the same number the Python model gave, so the two agree before any discounting.
B48: FY26 is the starting point (not discounted). Each later year = previous year × (1 + explicit growth, D18).
B51: STAGE 3 — Discounting the forecast to today's value | K51: NOTES — plain-language reasons
B52: Money in the future is worth less than money today, so each forecast year's cash flow is scaled down to its value today before we add them up. The scaling factor is 1 divided by (1+WACC) raised to the year number — the same simple method as the Python model (this replaces the earlier XNPV function). Multiply each year's cash flow by its factor, then add the five together to get the value of the forecast period in today's money. The terminal value — usually the larger part — is handled next.
B58: Discounting steps | E58: FY27F | F58: FY28F | G58: FY29F | H58: FY30F | I58: FY31F
B59: Time period t (yrs) | E59: 1 | F59: =E59+1 -> 2 | G59: =F59+1 -> 3 | H59: =G59+1 -> 4 | I59: =H59+1 -> 5 | K59: How many years ahead each cash flow is: year 1 is FY27, up to year 5 in FY31.
B60: Discount factor 1/(1+WACC)^t | E60: =1/(1+$D$16)^E59 -> 0.88739354 | F60: =1/(1+$D$16)^F59 -> 0.78746729 | G60: =1/(1+$D$16)^G59 -> 0.69879338 | H60: =1/(1+$D$16)^H59 -> 0.62010473 | I60: =1/(1+$D$16)^I59 -> 0.55027693 | K60: How much ₹1 in that future year is worth today, found with 1 ÷ (1+WACC) raised to the year number. It shrinks each year, because money in hand now is worth more than the same money later.
B61: Unlevered FCF (from Stage 2) | E61: =E46 -> 53000.933 | F61: =F46 -> 56180.989 | G61: =G46 -> 59551.848 | H61: =H46 -> 63124.959 | I61: =I46 -> 66912.457 | K61: The free cash flow figures copied down from Stage 2.
B62: PV of FCF (= FCF × factor) | E62: =E61*E60 -> 47032.685 | F62: =F61*F60 -> 44240.691 | G62: =G61*G60 -> 41614.437 | H62: =H61*H60 -> 39144.086 | I62: =I61*I60 -> 36820.381 | K62: Each year's cash flow multiplied by its discount factor — its worth in today's money.
B64: PV of explicit FCFs (add the 5) | D64: =SUM(E62:I62) -> 208852.28 | K64: Simply add the five discounted cash flows together. Plain addition — no special function.
B67: STAGE 4 — Terminal value (the worth of everything after FY31) | K67: NOTES — plain-language reasons
...

Sheet Summary
B2: TCS — DCF Valuation Summary
B3: All figures INR crore unless per-share · Consolidated · see 'DCF Model' sheet for workings
B5: Key assumptions
B6: WACC | D6: ='DCF Model'!D16 -> 0.12689574
B7: Terminal growth (g) | D7: ='DCF Model'!D17 -> 0.05
B8: Explicit growth | D8: ='DCF Model'!D18 -> 0.06
B9: Tax rate | D9: ='DCF Model'!D15 -> 0.24
B10: Shares outstanding (cr) | D10: ='DCF Model'!D22 -> 361.81
B11: Current price (INR) | D11: ='DCF Model'!D21 -> 2465
B13: Valuation build
B14: PV of explicit FCFs (FY27–31) | D14: ='DCF Model'!D64 -> 208852.28
B15: PV of terminal value | D15: ='DCF Model'!D83 -> 502776.85
B16: Enterprise Value | D16: ='DCF Model'!D85 -> 711629.13
B17: Plus: Cash & Investments | D17: ='DCF Model'!D24 -> 50020
B18: Less: Debt | D18: ='DCF Model'!D23 -> 11283
B19: Equity Value | D19: ='DCF Model'!D101 -> 750366.13
B21: Result
B22: Value / share (INR) | D22: ='DCF Model'!D103 -> 2073.9231
B23: Market price / share (INR) | D23: ='DCF Model'!D21 -> 2465
B24: Upside / (downside) | D24: ='DCF Model'!D110 -> -0.15865187
B25: Call | D25: ='DCF Model'!D111 -> OVERVALUED
B27: Thesis: at the base case (WACC about 12.7%, growth 5%) TCS looks modestly overvalued. It only looks cheap at a WACC below 11.5% or growth near 6%. These figures match the Python model to the rupee through enterprise value.
